{
  "unknown_error": "An internal problem has occurred please check again later"
}
